Workbook

Sheet Summary
A1: RENTAL INCOME — UNIT SUMMARY
A2: Balances update automatically from each unit ledger. Red = arrears, Green = paid/credit.
A3: Unit | B3: Tenant | C3: Rent | D3: Garbage | E3: Deposit Held | F3: Current Balance | G3: Months Out. | H3: Status | I3: Priority
A4: C1 | B4: ='C1'!J3 | C4: ='C1'!D3 | D4: ='C1'!F3 | E4: ='C1'!L3 | F4: ='C1'!H3 | G4: =IF(C4+D4=0,0,MAX(0,F4)/(C4+D4)) | H4: =IF(F4<=0,"Paid / Credit",IF(G4<1,"<1 month",IF(G4<2,"1–2 months",IF(G4<3,"2–3 months",">3 months")))) | I4: =IF(F4<=0,"PAID",IF(G4<1,"LOW",IF(G4<2,"MEDIUM","HIGH")))
A5: B3 | B5: ='B3'!J3 | C5: ='B3'!D3 | D5: ='B3'!F3 | E5: ='B3'!L3 | F5: ='B3'!H3 | G5: =IF(C5+D5=0,0,MAX(0,F5)/(C5+D5)) | H5: =IF(F5<=0,"Paid / Credit",IF(G5<1,"<1 month",IF(G5<2,"1–2 months",IF(G5<3,"2–3 months",">3 months")))) | I5: =IF(F5<=0,"PAID",IF(G5<1,"LOW",IF(G5<2,"MEDIUM","HIGH")))
A6: A7 | B6: ='A7'!J3 | C6: ='A7'!D3 | D6: ='A7'!F3 | E6: ='A7'!L3 | F6: ='A7'!H3 | G6: =IF(C6+D6=0,0,MAX(0,F6)/(C6+D6)) | H6: =IF(F6<=0,"Paid / Credit",IF(G6<1,"<1 month",IF(G6<2,"1–2 months",IF(G6<3,"2–3 months",">3 months")))) | I6: =IF(F6<=0,"PAID",IF(G6<1,"LOW",IF(G6<2,"MEDIUM","HIGH")))
A7: A6 | B7: ='A6'!J3 | C7: ='A6'!D3 | D7: ='A6'!F3 | E7: ='A6'!L3 | F7: ='A6'!H3 | G7: =IF(C7+D7=0,0,MAX(0,F7)/(C7+D7)) | H7: =IF(F7<=0,"Paid / Credit",IF(G7<1,"<1 month",IF(G7<2,"1–2 months",IF(G7<3,"2–3 months",">3 months")))) | I7: =IF(F7<=0,"PAID",IF(G7<1,"LOW",IF(G7<2,"MEDIUM","HIGH")))
A8: C3 | B8: ='C3'!J3 | C8: ='C3'!D3 | D8: ='C3'!F3 | E8: ='C3'!L3 | F8: ='C3'!H3 | G8: =IF(C8+D8=0,0,MAX(0,F8)/(C8+D8)) | H8: =IF(F8<=0,"Paid / Credit",IF(G8<1,"<1 month",IF(G8<2,"1–2 months",IF(G8<3,"2–3 months",">3 months")))) | I8: =IF(F8<=0,"PAID",IF(G8<1,"LOW",IF(G8<2,"MEDIUM","HIGH")))
A9: A1 | B9: ='A1'!J3 | C9: ='A1'!D3 | D9: ='A1'!F3 | E9: ='A1'!L3 | F9: ='A1'!H3 | G9: =IF(C9+D9=0,0,MAX(0,F9)/(C9+D9)) | H9: =IF(F9<=0,"Paid / Credit",IF(G9<1,"<1 month",IF(G9<2,"1–2 months",IF(G9<3,"2–3 months",">3 months")))) | I9: =IF(F9<=0,"PAID",IF(G9<1,"LOW",IF(G9<2,"MEDIUM","HIGH")))
A10: B1 | B10: ='B1'!J3 | C10: ='B1'!D3 | D10: ='B1'!F3 | E10: ='B1'!L3 | F10: ='B1'!H3 | G10: =IF(C10+D10=0,0,MAX(0,F10)/(C10+D10)) | H10: =IF(F10<=0,"Paid / Credit",IF(G10<1,"<1 month",IF(G10<2,"1–2 months",IF(G10<3,"2–3 months",">3 months")))) | I10: =IF(F10<=0,"PAID",IF(G10<1,"LOW",IF(G10<2,"MEDIUM","HIGH")))
A11: C2 | B11: ='C2'!J3 | C11: ='C2'!D3 | D11: ='C2'!F3 | E11: ='C2'!L3 | F11: ='C2'!H3 | G11: =IF(C11+D11=0,0,MAX(0,F11)/(C11+D11)) | H11: =IF(F11<=0,"Paid / Credit",IF(G11<1,"<1 month",IF(G11<2,"1–2 months",IF(G11<3,"2–3 months",">3 months")))) | I11: =IF(F11<=0,"PAID",IF(G11<1,"LOW",IF(G11<2,"MEDIUM","HIGH")))
A12: A2 | B12: ='A2'!J3 | C12: ='A2'!D3 | D12: ='A2'!F3 | E12: ='A2'!L3 | F12: ='A2'!H3 | G12: =IF(C12+D12=0,0,MAX(0,F12)/(C12+D12)) | H12: =IF(F12<=0,"Paid / Credit",IF(G12<1,"<1 month",IF(G12<2,"1–2 months",IF(G12<3,"2–3 months",">3 months")))) | I12: =IF(F12<=0,"PAID",IF(G12<1,"LOW",IF(G12<2,"MEDIUM","HIGH")))
A13: A3 | B13: ='A3'!J3 | C13: ='A3'!D3 | D13: ='A3'!F3 | E13: ='A3'!L3 | F13: ='A3'!H3 | G13: =IF(C13+D13=0,0,MAX(0,F13)/(C13+D13)) | H13: =IF(F13<=0,"Paid / Credit",IF(G13<1,"<1 month",IF(G13<2,"1–2 months",IF(G13<3,"2–3 months",">3 months")))) | I13: =IF(F13<=0,"PAID",IF(G13<1,"LOW",IF(G13<2,"MEDIUM","HIGH")))
A14: A4 | B14: ='A4'!J3 | C14: ='A4'!D3 | D14: ='A4'!F3 | E14: ='A4'!L3 | F14: ='A4'!H3 | G14: =IF(C14+D14=0,0,MAX(0,F14)/(C14+D14)) | H14: =IF(F14<=0,"Paid / Credit",IF(G14<1,"<1 month",IF(G14<2,"1–2 months",IF(G14<3,"2–3 months",">3 months")))) | I14: =IF(F14<=0,"PAID",IF(G14<1,"LOW",IF(G14<2,"MEDIUM","HIGH")))
A15: A5 | B15: ='A5'!J3 | C15: ='A5'!D3 | D15: ='A5'!F3 | E15: ='A5'!L3 | F15: ='A5'!H3 | G15: =IF(C15+D15=0,0,MAX(0,F15)/(C15+D15)) | H15: =IF(F15<=0,"Paid / Credit",IF(G15<1,"<1 month",IF(G15<2,"1–2 months",IF(G15<3,"2–3 months",">3 months")))) | I15: =IF(F15<=0,"PAID",IF(G15<1,"LOW",IF(G15<2,"MEDIUM","HIGH")))
A16: B2 | B16: ='B2'!J3 | C16: ='B2'!D3 | D16: ='B2'!F3 | E16: ='B2'!L3 | F16: ='B2'!H3 | G16: =IF(C16+D16=0,0,MAX(0,F16)/(C16+D16)) | H16: =IF(F16<=0,"Paid / Credit",IF(G16<1,"<1 month",IF(G16<2,"1–2 months",IF(G16<3,"2–3 months",">3 months")))) | I16: =IF(F16<=0,"PAID",IF(G16<1,"LOW",IF(G16<2,"MEDIUM","HIGH")))
A17: Shop 1 | B17: ='Shop 1'!J3 | C17: ='Shop 1'!D3 | D17: ='Shop 1'!F3 | E17: ='Shop 1'!L3 | F17: ='Shop 1'!H3 | G17: =IF(C17+D17=0,0,MAX(0,F17)/(C17+D17)) | H17: =IF(F17<=0,"Paid / Credit",IF(G17<1,"<1 month",IF(G17<2,"1–2 months",IF(G17<3,"2–3 months",">3 months")))) | I17: =IF(F17<=0,"PAID",IF(G17<1,"LOW",IF(G17<2,"MEDIUM","HIGH")))
A18: Shop 2 | B18: ='Shop 2'!J3 | C18: ='Shop 2'!D3 | D18: ='Shop 2'!F3 | E18: 5000 | F18: ='Shop 2'!H3 | G18: =IF(C18+D18=0,0,MAX(0,F18)/(C18+D18)) | H18: =IF(F18<=0,"Paid / Credit",IF(G18<1,"<1 month",IF(G18<2,"1–2 months",IF(G18<3,"2–3 months",">3 months")))) | I18: =IF(F18<=0,"PAID",IF(G18<1,"LOW",IF(G18<2,"MEDIUM","HIGH")))
A21: UNIT STATUS — all units
A22: Every unit is listed. Priority and suggested action update automatically. Click any column header arrow in the table below to Sort or Filter (e.g. Balance).
A23: Unit | B23: Tenant | C23: Balance | D23: Months | E23: Priority | F23: Suggested Action
A24: =A4 | B24: =B4 | C24: =F4 | D24: =G4 | E24: =IF(F4<=0,"PAID",IF(G4<1,"LOW",IF(G4<2,"MEDIUM","HIGH"))) | F24: =IF(F4<=0,"NO ACTION NEEDED",IF(G4<1,"MONITOR",IF(G4<2,"FOLLOW UP","URGENT")))
A25: =A5 | B25: =B5 | C25: =F5 | D25: =G5 | E25: =IF(F5<=0,"PAID",IF(G5<1,"LOW",IF(G5<2,"MEDIUM","HIGH"))) | F25: =IF(F5<=0,"NO ACTION NEEDED",IF(G5<1,"MONITOR",IF(G5<2,"FOLLOW UP","URGENT")))
A26: =A6 | B26: =B6 | C26: =F6 | D26: =G6 | E26: =IF(F6<=0,"PAID",IF(G6<1,"LOW",IF(G6<2,"MEDIUM","HIGH"))) | F26: =IF(F6<=0,"NO ACTION NEEDED",IF(G6<1,"MONITOR",IF(G6<2,"FOLLOW UP","URGENT")))
A27: =A7 | B27: =B7 | C27: =F7 | D27: =G7 | E27: =IF(F7<=0,"PAID",IF(G7<1,"LOW",IF(G7<2,"MEDIUM","HIGH"))) | F27: =IF(F7<=0,"NO ACTION NEEDED",IF(G7<1,"MONITOR",IF(G7<2,"FOLLOW UP","URGENT")))
A28: =A8 | B28: =B8 | C28: =F8 | D28: =G8 | E28: =IF(F8<=0,"PAID",IF(G8<1,"LOW",IF(G8<2,"MEDIUM","HIGH"))) | F28: =IF(F8<=0,"NO ACTION NEEDED",IF(G8<1,"MONITOR",IF(G8<2,"FOLLOW UP","URGENT")))
A29: =A9 | B29: =B9 | C29: =F9 | D29: =G9 | E29: =IF(F9<=0,"PAID",IF(G9<1,"LOW",IF(G9<2,"MEDIUM","HIGH"))) | F29: =IF(F9<=0,"NO ACTION NEEDED",IF(G9<1,"MONITOR",IF(G9<2,"FOLLOW UP","URGENT")))
A30: =A10 | B30: =B10 | C30: =F10 | D30: =G10 | E30: =IF(F10<=0,"PAID",IF(G10<1,"LOW",IF(G10<2,"MEDIUM","HIGH"))) | F30: =IF(F10<=0,"NO ACTION NEEDED",IF(G10<1,"MONITOR",IF(G10<2,"FOLLOW UP","URGENT")))
A31: =A11 | B31: =B11 | C31: =F11 | D31: =G11 | E31: =IF(F11<=0,"PAID",IF(G11<1,"LOW",IF(G11<2,"MEDIUM","HIGH"))) | F31: =IF(F11<=0,"NO ACTION NEEDED",IF(G11<1,"MONITOR",IF(G11<2,"FOLLOW UP","URGENT")))
A32: =A12 | B32: =B12 | C32: =F12 | D32: =G12 | E32: =IF(F12<=0,"PAID",IF(G12<1,"LOW",IF(G12<2,"MEDIUM","HIGH"))) | F32: =IF(F12<=0,"NO ACTION NEEDED",IF(G12<1,"MONITOR",IF(G12<2,"FOLLOW UP","URGENT")))
A33: =A13 | B33: =B13 | C33: =F13 | D33: =G13 | E33: =IF(F13<=0,"PAID",IF(G13<1,"LOW",IF(G13<2,"MEDIUM","HIGH"))) | F33: =IF(F13<=0,"NO ACTION NEEDED",IF(G13<1,"MONITOR",IF(G13<2,"FOLLOW UP","URGENT")))
A34: =A14 | B34: =B14 | C34: =F14 | D34: =G14 | E34: =IF(F14<=0,"PAID",IF(G14<1,"LOW",IF(G14<2,"MEDIUM","HIGH"))) | F34: =IF(F14<=0,"NO ACTION NEEDED",IF(G14<1,"MONITOR",IF(G14<2,"FOLLOW UP","URGENT")))
A35: =A15 | B35: =B15 | C35: =F15 | D35: =G15 | E35: =IF(F15<=0,"PAID",IF(G15<1,"LOW",IF(G15<2,"MEDIUM","HIGH"))) | F35: =IF(F15<=0,"NO ACTION NEEDED",IF(G15<1,"MONITOR",IF(G15<2,"FOLLOW UP","URGENT")))
... A38: =A18 | B38: =B18 | C38: =F18 | D38: =G18 | E38: =IF(F18<=0,"PAID",IF(G18<1,"LOW",IF(G18<2,"MEDIUM","HIGH"))) | F38: =IF(F18<=0,"NO ACTION NEEDED",IF(G18<1,"MONITOR",IF(G18<2,"FOLLOW UP","URGENT")))

Sheet Statement
A1: TENANT STATEMENT
A2: Select a unit in cell B3. The statement below updates automatically. Print this sheet (or export to PDF) to share with the tenant.
A3: Select Unit: | B3: A1 | C3: ← Change this to generate another tenant's statement
A5: Unit | B5: =B3
A6: Tenant | B6: =IFERROR(INDEX(Summary!B4:B18,MATCH(B3,Summary!A4:A18,0)),"")
A7: Monthly Rent | B7: =IFERROR(INDEX(Summary!C4:C18,MATCH(B3,Summary!A4:A18,0)),0)
A8: Garbage Fee | B8: =IFERROR(INDEX(Summary!D4:D18,MATCH(B3,Summary!A4:A18,0)),0)
A9: Current Balance | B9: =IFERROR(INDEX(Summary!E4:E18,MATCH(B3,Summary!A4:A18,0)),0)
A10: Deposit Held | B10: =IFERROR(INDEX(Summary!E4:E18,MATCH(B3,Summary!A4:A18,0)),0)
A11: TRANSACTION HISTORY
A12: Date | B12: Month | C12: Description | D12: Rent Charged | E12: Garbage | F12: Payment Received | G12: Running Balance
A13: =IF(INDIRECT("'"&$B$3&"'!A6")="","",INDIRECT("'"&$B$3&"'!A6")) | B13: =IF(INDIRECT("'"&$B$3&"'!B6")="","",INDIRECT("'"&$B$3&"'!B6")) | C13: =IF(INDIRECT("'"&$B$3&"'!C6")="","",INDIRECT("'"&$B$3&"'!C6")) | D13: =IF(INDIRECT("'"&$B$3&"'!E6")="","",INDIRECT("'"&$B$3&"'!E6")) | E13: =IF(INDIRECT("'"&$B$3&"'!F6")="","",INDIRECT("'"&$B$3&"'!F6")) | F13: =IF(INDIRECT("'"&$B$3&"'!G6")="","",INDIRECT("'"&$B$3&"'!G6")) | G13: =IF(INDIRECT("'"&$B$3&"'!I6")="","",INDIRECT("'"&$B$3&"'!I6"))
A14: =IF(INDIRECT("'"&$B$3&"'!A7")="","",INDIRECT("'"&$B$3&"'!A7")) | B14: =IF(INDIRECT("'"&$B$3&"'!B7")="","",INDIRECT("'"&$B$3&"'!B7")) | C14: =IF(INDIRECT("'"&$B$3&"'!C7")="","",INDIRECT("'"&$B$3&"'!C7")) | D14: =IF(INDIRECT("'"&$B$3&"'!E7")="","",INDIRECT("'"&$B$3&"'!E7")) | E14: =IF(INDIRECT("'"&$B$3&"'!F7")="","",INDIRECT("'"&$B$3&"'!F7")) | F14: =IF(INDIRECT("'"&$B$3&"'!G7")="","",INDIRECT("'"&$B$3&"'!G7")) | G14: =IF(INDIRECT("'"&$B$3&"'!I7")="","",INDIRECT("'"&$B$3&"'!I7"))
A15: =IF(INDIRECT("'"&$B$3&"'!A8")="","",INDIRECT("'"&$B$3&"'!A8")) | B15: =IF(INDIRECT("'"&$B$3&"'!B8")="","",INDIRECT("'"&$B$3&"'!B8")) | C15: =IF(INDIRECT("'"&$B$3&"'!C8")="","",INDIRECT("'"&$B$3&"'!C8")) | D15: =IF(INDIRECT("'"&$B$3&"'!E8")="","",INDIRECT("'"&$B$3&"'!E8")) | E15: =IF(INDIRECT("'"&$B$3&"'!F8")="","",INDIRECT("'"&$B$3&"'!F8")) | F15: =IF(INDIRECT("'"&$B$3&"'!G8")="","",INDIRECT("'"&$B$3&"'!G8")) | G15: =IF(INDIRECT("'"&$B$3&"'!I8")="","",INDIRECT("'"&$B$3&"'!I8"))
A16: =IF(INDIRECT("'"&$B$3&"'!A9")="","",INDIRECT("'"&$B$3&"'!A9")) | B16: =IF(INDIRECT("'"&$B$3&"'!B9")="","",INDIRECT("'"&$B$3&"'!B9")) | C16: =IF(INDIRECT("'"&$B$3&"'!C9")="","",INDIRECT("'"&$B$3&"'!C9")) | D16: =IF(INDIRECT("'"&$B$3&"'!E9")="","",INDIRECT("'"&$B$3&"'!E9")) | E16: =IF(INDIRECT("'"&$B$3&"'!F9")="","",INDIRECT("'"&$B$3&"'!F9")) | F16: =IF(INDIRECT("'"&$B$3&"'!G9")="","",INDIRECT("'"&$B$3&"'!G9")) | G16: =IF(INDIRECT("'"&$B$3&"'!I9")="","",INDIRECT("'"&$B$3&"'!I9"))
A17: =IF(INDIRECT("'"&$B$3&"'!A10")="","",INDIRECT("'"&$B$3&"'!A10")) | B17: =IF(INDIRECT("'"&$B$3&"'!B10")="","",INDIRECT("'"&$B$3&"'!B10")) | C17: =IF(INDIRECT("'"&$B$3&"'!C10")="","",INDIRECT("'"&$B$3&"'!C10")) | D17: =IF(INDIRECT("'"&$B$3&"'!E10")="","",INDIRECT("'"&$B$3&"'!E10")) | E17: =IF(INDIRECT("'"&$B$3&"'!F10")="","",INDIRECT("'"&$B$3&"'!F10")) | F17: =IF(INDIRECT("'"&$B$3&"'!G10")="","",INDIRECT("'"&$B$3&"'!G10")) | G17: =IF(INDIRECT("'"&$B$3&"'!I10")="","",INDIRECT("'"&$B$3&"'!I10"))
A18: =IF(INDIRECT("'"&$B$3&"'!A11")="","",INDIRECT("'"&$B$3&"'!A11")) | B18: =IF(INDIRECT("'"&$B$3&"'!B11")="","",INDIRECT("'"&$B$3&"'!B11")) | C18: =IF(INDIRECT("'"&$B$3&"'!C11")="","",INDIRECT("'"&$B$3&"'!C11")) | D18: =IF(INDIRECT("'"&$B$3&"'!E11")="","",INDIRECT("'"&$B$3&"'!E11")) | E18: =IF(INDIRECT("'"&$B$3&"'!F11")="","",INDIRECT("'"&$B$3&"'!F11")) | F18: =IF(INDIRECT("'"&$B$3&"'!G11")="","",INDIRECT("'"&$B$3&"'!G11")) | G18: =IF(INDIRECT("'"&$B$3&"'!I11")="","",INDIRECT("'"&$B$3&"'!I11"))
A19: =IF(INDIRECT("'"&$B$3&"'!A12")="","",INDIRECT("'"&$B$3&"'!A12")) | B19: =IF(INDIRECT("'"&$B$3&"'!B12")="","",INDIRECT("'"&$B$3&"'!B12")) | C19: =IF(INDIRECT("'"&$B$3&"'!C12")="","",INDIRECT("'"&$B$3&"'!C12")) | D19: =IF(INDIRECT("'"&$B$3&"'!E12")="","",INDIRECT("'"&$B$3&"'!E12")) | E19: =IF(INDIRECT("'"&$B$3&"'!F12")="","",INDIRECT("'"&$B$3&"'!F12")) | F19: =IF(INDIRECT("'"&$B$3&"'!G12")="","",INDIRECT("'"&$B$3&"'!G12")) | G19: =IF(INDIRECT("'"&$B$3&"'!I12")="","",INDIRECT("'"&$B$3&"'!I12"))
A20: =IF(INDIRECT("'"&$B$3&"'!A13")="","",INDIRECT("'"&$B$3&"'!A13")) | B20: =IF(INDIRECT("'"&$B$3&"'!B13")="","",INDIRECT("'"&$B$3&"'!B13")) | C20: =IF(INDIRECT("'"&$B$3&"'!C13")="","",INDIRECT("'"&$B$3&"'!C13")) | D20: =IF(INDIRECT("'"&$B$3&"'!E13")="","",INDIRECT("'"&$B$3&"'!E13")) | E20: =IF(INDIRECT("'"&$B$3&"'!F13")="","",INDIRECT("'"&$B$3&"'!F13")) | F20: =IF(INDIRECT("'"&$B$3&"'!G13")="","",INDIRECT("'"&$B$3&"'!G13")) | G20: =IF(INDIRECT("'"&$B$3&"'!I13")="","",INDIRECT("'"&$B$3&"'!I13"))
A21: =IF(INDIRECT("'"&$B$3&"'!A14")="","",INDIRECT("'"&$B$3&"'!A14")) | B21: =IF(INDIRECT("'"&$B$3&"'!B14")="","",INDIRECT("'"&$B$3&"'!B14")) | C21: =IF(INDIRECT("'"&$B$3&"'!C14")="","",INDIRECT("'"&$B$3&"'!C14")) | D21: =IF(INDIRECT("'"&$B$3&"'!E14")="","",INDIRECT("'"&$B$3&"'!E14")) | E21: =IF(INDIRECT("'"&$B$3&"'!F14")="","",INDIRECT("'"&$B$3&"'!F14")) | F21: =IF(INDIRECT("'"&$B$3&"'!G14")="","",INDIRECT("'"&$B$3&"'!G14")) | G21: =IF(INDIRECT("'"&$B$3&"'!I14")="","",INDIRECT("'"&$B$3&"'!I14"))
A22: =IF(INDIRECT("'"&$B$3&"'!A15")="","",INDIRECT("'"&$B$3&"'!A15")) | B22: =IF(INDIRECT("'"&$B$3&"'!B15")="","",INDIRECT("'"&$B$3&"'!B15")) | C22: =IF(INDIRECT("'"&$B$3&"'!C15")="","",INDIRECT("'"&$B$3&"'!C15")) | D22: =IF(INDIRECT("'"&$B$3&"'!E15")="","",INDIRECT("'"&$B$3&"'!E15")) | E22: =IF(INDIRECT("'"&$B$3&"'!F15")="","",INDIRECT("'"&$B$3&"'!F15")) | F22: =IF(INDIRECT("'"&$B$3&"'!G15")="","",INDIRECT("'"&$B$3&"'!G15")) | G22: =IF(INDIRECT("'"&$B$3&"'!I15")="","",INDIRECT("'"&$B$3&"'!I15"))
A23: =IF(INDIRECT("'"&$B$3&"'!A16")="","",INDIRECT("'"&$B$3&"'!A16")) | B23: =IF(INDIRECT("'"&$B$3&"'!B16")="","",INDIRECT("'"&$B$3&"'!B16")) | C23: =IF(INDIRECT("'"&$B$3&"'!C16")="","",INDIRECT("'"&$B$3&"'!C16")) | D23: =IF(INDIRECT("'"&$B$3&"'!E16")="","",INDIRECT("'"&$B$3&"'!E16")) | E23: =IF(INDIRECT("'"&$B$3&"'!F16")="","",INDIRECT("'"&$B$3&"'!F16")) | F23: =IF(INDIRECT("'"&$B$3&"'!G16")="","",INDIRECT("'"&$B$3&"'!G16")) | G23: =IF(INDIRECT("'"&$B$3&"'!I16")="","",INDIRECT("'"&$B$3&"'!I16"))
A24: =IF(INDIRECT("'"&$B$3&"'!A17")="","",INDIRECT("'"&$B$3&"'!A17")) | B24: =IF(INDIRECT("'"&$B$3&"'!B17")="","",INDIRECT("'"&$B$3&"'!B17")) | C24: =IF(INDIRECT("'"&$B$3&"'!C17")="","",INDIRECT("'"&$B$3&"'!C17")) | D24: =IF(INDIRECT("'"&$B$3&"'!E17")="","",INDIRECT("'"&$B$3&"'!E17")) | E24: =IF(INDIRECT("'"&$B$3&"'!F17")="","",INDIRECT("'"&$B$3&"'!F17")) | F24: =IF(INDIRECT("'"&$B$3&"'!G17")="","",INDIRECT("'"&$B$3&"'!G17")) | G24: =IF(INDIRECT("'"&$B$3&"'!I17")="","",INDIRECT("'"&$B$3&"'!I17"))
A25: =IF(INDIRECT("'"&$B$3&"'!A18")="","",INDIRECT("'"&$B$3&"'!A18")) | B25: =IF(INDIRECT("'"&$B$3&"'!B18")="","",INDIRECT("'"&$B$3&"'!B18")) | C25: =IF(INDIRECT("'"&$B$3&"'!C18")="","",INDIRECT("'"&$B$3&"'!C18")) | D25: =IF(INDIRECT("'"&$B$3&"'!E18")="","",INDIRECT("'"&$B$3&"'!E18")) | E25: =IF(INDIRECT("'"&$B$3&"'!F18")="","",INDIRECT("'"&$B$3&"'!F18")) | F25: =IF(INDIRECT("'"&$B$3&"'!G18")="","",INDIRECT("'"&$B$3&"'!G18")) | G25: =IF(INDIRECT("'"&$B$3&"'!I18")="","",INDIRECT("'"&$B$3&"'!I18"))
A26: =IF(INDIRECT("'"&$B$3&"'!A19")="","",INDIRECT("'"&$B$3&"'!A19")) | B26: =IF(INDIRECT("'"&$B$3&"'!B19")="","",INDIRECT("'"&$B$3&"'!B19")) | C26: =IF(INDIRECT("'"&$B$3&"'!C19")="","",INDIRECT("'"&$B$3&"'!C19")) | D26: =IF(INDIRECT("'"&$B$3&"'!E19")="","",INDIRECT("'"&$B$3&"'!E19")) | E26: =IF(INDIRECT("'"&$B$3&"'!F19")="","",INDIRECT("'"&$B$3&"'!F19")) | F26: =IF(INDIRECT("'"&$B$3&"'!G19")="","",INDIRECT("'"&$B$3&"'!G19")) | G26: =IF(INDIRECT("'"&$B$3&"'!I19")="","",INDIRECT("'"&$B$3&"'!I19"))
A27: =IF(INDIRECT("'"&$B$3&"'!A20")="","",INDIRECT("'"&$B$3&"'!A20")) | B27: =IF(INDIRECT("'"&$B$3&"'!B20")="","",INDIRECT("'"&$B$3&"'!B20")) | C27: =IF(INDIRECT("'"&$B$3&"'!C20")="","",INDIRECT("'"&$B$3&"'!C20")) | D27: =IF(INDIRECT("'"&$B$3&"'!E20")="","",INDIRECT("'"&$B$3&"'!E20")) | E27: =IF(INDIRECT("'"&$B$3&"'!F20")="","",INDIRECT("'"&$B$3&"'!F20")) | F27: =IF(INDIRECT("'"&$B$3&"'!G20")="","",INDIRECT("'"&$B$3&"'!G20")) | G27: =IF(INDIRECT("'"&$B$3&"'!I20")="","",INDIRECT("'"&$B$3&"'!I20"))
A28: =IF(INDIRECT("'"&$B$3&"'!A21")="","",INDIRECT("'"&$B$3&"'!A21")) | B28: =IF(INDIRECT("'"&$B$3&"'!B21")="","",INDIRECT("'"&$B$3&"'!B21")) | C28: =IF(INDIRECT("'"&$B$3&"'!C21")="","",INDIRECT("'"&$B$3&"'!C21")) | D28: =IF(INDIRECT("'"&$B$3&"'!E21")="","",INDIRECT("'"&$B$3&"'!E21")) | E28: =IF(INDIRECT("'"&$B$3&"'!F21")="","",INDIRECT("'"&$B$3&"'!F21")) | F28: =IF(INDIRECT("'"&$B$3&"'!G21")="","",INDIRECT("'"&$B$3&"'!G21")) | G28: =IF(INDIRECT("'"&$B$3&"'!I21")="","",INDIRECT("'"&$B$3&"'!I21"))
A29: =IF(INDIRECT("'"&$B$3&"'!A22")="","",INDIRECT("'"&$B$3&"'!A22")) | B29: =IF(INDIRECT("'"&$B$3&"'!B22")="","",INDIRECT("'"&$B$3&"'!B22")) | C29: =IF(INDIRECT("'"&$B$3&"'!C22")="","",INDIRECT("'"&$B$3&"'!C22")) | D29: =IF(INDIRECT("'"&$B$3&"'!E22")="","",INDIRECT("'"&$B$3&"'!E22")) | E29: =IF(INDIRECT("'"&$B$3&"'!F22")="","",INDIRECT("'"&$B$3&"'!F22")) | F29: =IF(INDIRECT("'"&$B$3&"'!G22")="","",INDIRECT("'"&$B$3&"'!G22")) | G29: =IF(INDIRECT("'"&$B$3&"'!I22")="","",INDIRECT("'"&$B$3&"'!I22"))
A30: =IF(INDIRECT("'"&$B$3&"'!A23")="","",INDIRECT("'"&$B$3&"'!A23")) | B30: =IF(INDIRECT("'"&$B$3&"'!B23")="","",INDIRECT("'"&$B$3&"'!B23")) | C30: =IF(INDIRECT("'"&$B$3&"'!C23")="","",INDIRECT("'"&$B$3&"'!C23")) | D30: =IF(INDIRECT("'"&$B$3&"'!E23")="","",INDIRECT("'"&$B$3&"'!E23")) | E30: =IF(INDIRECT("'"&$B$3&"'!F23")="","",INDIRECT("'"&$B$3&"'!F23")) | F30: =IF(INDIRECT("'"&$B$3&"'!G23")="","",INDIRECT("'"&$B$3&"'!G23")) | G30: =IF(INDIRECT("'"&$B$3&"'!I23")="","",INDIRECT("'"&$B$3&"'!I23"))
A31: =IF(INDIRECT("'"&$B$3&"'!A24")="","",INDIRECT("'"&$B$3&"'!A24")) | B31: =IF(INDIRECT("'"&$B$3&"'!B24")="","",INDIRECT("'"&$B$3&"'!B24")) | C31: =IF(INDIRECT("'"&$B$3&"'!C24")="","",INDIRECT("'"&$B$3&"'!C24")) | D31: =IF(INDIRECT("'"&$B$3&"'!E24")="","",INDIRECT("'"&$B$3&"'!E24")) | E31: =IF(INDIRECT("'"&$B$3&"'!F24")="","",INDIRECT("'"&$B$3&"'!F24")) | F31: =IF(INDIRECT("'"&$B$3&"'!G24")="","",INDIRECT("'"&$B$3&"'!G24")) | G31: =IF(INDIRECT("'"&$B$3&"'!I24")="","",INDIRECT("'"&$B$3&"'!I24"))
A32: =IF(INDIRECT("'"&$B$3&"'!A25")="","",INDIRECT("'"&$B$3&"'!A25")) | B32: =IF(INDIRECT("'"&$B$3&"'!B25")="","",INDIRECT("'"&$B$3&"'!B25")) | C32: =IF(INDIRECT("'"&$B$3&"'!C25")="","",INDIRECT("'"&$B$3&"'!C25")) | D32: =IF(INDIRECT("'"&$B$3&"'!E25")="","",INDIRECT("'"&$B$3&"'!E25")) | E32: =IF(INDIRECT("'"&$B$3&"'!F25")="","",INDIRECT("'"&$B$3&"'!F25")) | F32: =IF(INDIRECT("'"&$B$3&"'!G25")="","",INDIRECT("'"&$B$3&"'!G25")) | G32: =IF(INDIRECT("'"&$B$3&"'!I25")="","",INDIRECT("'"&$B$3&"'!I25"))
A33: =IF(INDIRECT("'"&$B$3&"'!A26")="","",INDIRECT("'"&$B$3&"'!A26")) | B33: =IF(INDIRECT("'"&$B$3&"'!B26")="","",INDIRECT("'"&$B$3&"'!B26")) | C33: =IF(INDIRECT("'"&$B$3&"'!C26")="","",INDIRECT("'"&$B$3&"'!C26")) | D33: =IF(INDIRECT("'"&$B$3&"'!E26")="","",INDIRECT("'"&$B$3&"'!E26")) | E33: =IF(INDIRECT("'"&$B$3&"'!F26")="","",INDIRECT("'"&$B$3&"'!F26")) | F33: =IF(INDIRECT("'"&$B$3&"'!G26")="","",INDIRECT("'"&$B$3&"'!G26")) | G33: =IF(INDIRECT("'"&$B$3&"'!I26")="","",INDIRECT("'"&$B$3&"'!I26"))
A34: =IF(INDIRECT("'"&$B$3&"'!A27")="","",INDIRECT("'"&$B$3&"'!A27")) | B34: =IF(INDIRECT("'"&$B$3&"'!B27")="","",INDIRECT("'"&$B$3&"'!B27")) | C34: =IF(INDIRECT("'"&$B$3&"'!C27")="","",INDIRECT("'"&$B$3&"'!C27")) | D34: =IF(INDIRECT("'"&$B$3&"'!E27")="","",INDIRECT("'"&$B$3&"'!E27")) | E34: =IF(INDIRECT("'"&$B$3&"'!F27")="","",INDIRECT("'"&$B$3&"'!F27")) | F34: =IF(INDIRECT("'"&$B$3&"'!G27")="","",INDIRECT("'"&$B$3&"'!G27")) | G34: =IF(INDIRECT("'"&$B$3&"'!I27")="","",INDIRECT("'"&$B$3&"'!I27"))
A35: =IF(INDIRECT("'"&$B$3&"'!A28")="","",INDIRECT("'"&$B$3&"'!A28")) | B35: =IF(INDIRECT("'"&$B$3&"'!B28")="","",INDIRECT("'"&$B$3&"'!B28")) | C35: =IF(INDIRECT("'"&$B$3&"'!C28")="","",INDIRECT("'"&$B$3&"'!C28")) | D35: =IF(INDIRECT("'"&$B$3&"'!E28")="","",INDIRECT("'"&$B$3&"'!E28")) | E35: =IF(INDIRECT("'"&$B$3&"'!F28")="","",INDIRECT("'"&$B$3&"'!F28")) | F35: =IF(INDIRECT("'"&$B$3&"'!G28")="","",INDIRECT("'"&$B$3&"'!G28")) | G35: =IF(INDIRECT("'"&$B$3&"'!I28")="","",INDIRECT("'"&$B$3&"'!I28"))
A36: =IF(INDIRECT("'"&$B$3&"'!A29")="","",INDIRECT("'"&$B$3&"'!A29")) | B36: =IF(INDIRECT("'"&$B$3&"'!B29")="","",INDIRECT("'"&$B$3&"'!B29")) | C36: =IF(INDIRECT("'"&$B$3&"'!C29")="","",INDIRECT("'"&$B$3&"'!C29")) | D36: =IF(INDIRECT("'"&$B$3&"'!E29")="","",INDIRECT("'"&$B$3&"'!E29")) | E36: =IF(INDIRECT("'"&$B$3&"'!F29")="","",INDIRECT("'"&$B$3&"'!F29")) | F36: =IF(INDIRECT("'"&$B$3&"'!G29")="","",INDIRECT("'"&$B$3&"'!G29")) | G36: =IF(INDIRECT("'"&$B$3&"'!I29")="","",INDIRECT("'"&$B$3&"'!I29"))
A37: =IF(INDIRECT("'"&$B$3&"'!A30")="","",INDIRECT("'"&$B$3&"'!A30")) | B37: =IF(INDIRECT("'"&$B$3&"'!B30")="","",INDIRECT("'"&$B$3&"'!B30")) | C37: =IF(INDIRECT("'"&$B$3&"'!C30")="","",INDIRECT("'"&$B$3&"'!C30")) | D37: =IF(INDIRECT("'"&$B$3&"'!E30")="","",INDIRECT("'"&$B$3&"'!E30")) | E37: =IF(INDIRECT("'"&$B$3&"'!F30")="","",INDIRECT("'"&$B$3&"'!F30")) | F37: =IF(INDIRECT("'"&$B$3&"'!G30")="","",INDIRECT("'"&$B$3&"'!G30")) | G37: =IF(INDIRECT("'"&$B$3&"'!I30")="","",INDIRECT("'"&$B$3&"'!I30"))
A38: =IF(INDIRECT("'"&$B$3&"'!A31")="","",INDIRECT("'"&$B$3&"'!A31")) | B38: =IF(INDIRECT("'"&$B$3&"'!B31")="","",INDIRECT("'"&$B$3&"'!B31")) | C38: =IF(INDIRECT("'"&$B$3&"'!C31")="","",INDIRECT("'"&$B$3&"'!C31")) | D38: =IF(INDIRECT("'"&$B$3&"'!E31")="","",INDIRECT("'"&$B$3&"'!E31")) | E38: =IF(INDIRECT("'"&$B$3&"'!F31")="","",INDIRECT("'"&$B$3&"'!F31")) | F38: =IF(INDIRECT("'"&$B$3&"'!G31")="","",INDIRECT("'"&$B$3&"'!G31")) | G38: =IF(INDIRECT("'"&$B$3&"'!I31")="","",INDIRECT("'"&$B$3&"'!I31"))
A39: =IF(INDIRECT("'"&$B$3&"'!A32")="","",INDIRECT("'"&$B$3&"'!A32")) | B39: =IF(INDIRECT("'"&$B$3&"'!B32")="","",INDIRECT("'"&$B$3&"'!B32")) | C39: =IF(INDIRECT("'"&$B$3&"'!C32")="","",INDIRECT("'"&$B$3&"'!C32")) | D39: =IF(INDIRECT("'"&$B$3&"'!E32")="","",INDIRECT("'"&$B$3&"'!E32")) | E39: =IF(INDIRECT("'"&$B$3&"'!F32")="","",INDIRECT("'"&$B$3&"'!F32")) | F39: =IF(INDIRECT("'"&$B$3&"'!G32")="","",INDIRECT("'"&$B$3&"'!G32")) | G39: =IF(INDIRECT("'"&$B$3&"'!I32")="","",INDIRECT("'"&$B$3&"'!I32"))
A40: =IF(INDIRECT("'"&$B$3&"'!A33")="","",INDIRECT("'"&$B$3&"'!A33")) | B40: =IF(INDIRECT("'"&$B$3&"'!B33")="","",INDIRECT("'"&$B$3&"'!B33")) | C40: =IF(INDIRECT("'"&$B$3&"'!C33")="","",INDIRECT("'"&$B$3&"'!C33")) | D40: =IF(INDIRECT("'"&$B$3&"'!E33")="","",INDIRECT("'"&$B$3&"'!E33")) | E40: =IF(INDIRECT("'"&$B$3&"'!F33")="","",INDIRECT("'"&$B$3&"'!F33")) | F40: =IF(INDIRECT("'"&$B$3&"'!G33")="","",INDIRECT("'"&$B$3&"'!G33")) | G40: =IF(INDIRECT("'"&$B$3&"'!I33")="","",INDIRECT("'"&$B$3&"'!I33"))
A41: =IF(INDIRECT("'"&$B$3&"'!A34")="","",INDIRECT("'"&$B$3&"'!A34")) | B41: =IF(INDIRECT("'"&$B$3&"'!B34")="","",INDIRECT("'"&$B$3&"'!B34")) | C41: =IF(INDIRECT("'"&$B$3&"'!C34")="","",INDIRECT("'"&$B$3&"'!C34")) | D41: =IF(INDIRECT("'"&$B$3&"'!E34")="","",INDIRECT("'"&$B$3&"'!E34")) | E41: =IF(INDIRECT("'"&$B$3&"'!F34")="","",INDIRECT("'"&$B$3&"'!F34")) | F41: =IF(INDIRECT("'"&$B$3&"'!G34")="","",INDIRECT("'"&$B$3&"'!G34")) | G41: =IF(INDIRECT("'"&$B$3&"'!I34")="","",INDIRECT("'"&$B$3&"'!I34"))
...

Sheet Archive
A1: TENANCY ARCHIVE — previous tenants only
A2: When a tenant vacates: copy their full ledger from the unit sheet into this Archive, then clear the unit sheet for the new tenant. Unit sheets should only show the CURRENT tenant.
A4: CLOSED TENANCIES REGISTER
A5: Unit | B5: Tenant Name | C5: Move-in Date | D5: Move-out Date | E5: Final Balance | F5: Deposit Held | G5: Deposit Refunded | H5: Deposit Forfeited | I5: Reason for Leaving | J5: Notes | K5: Arrears Outcome
B6: =IF(A6="","",IFERROR(INDIRECT("'"&A6&"'!J3"),"")) | C6: =IF(A6="","",IFERROR(INDEX(INDIRECT("'"&A6&"'!A6:A200"),MATCH(TRUE,INDEX(INDIRECT("'"&A6&"'!A6:A200")<>"",0),0)),"")) | E6: =IF(A6="","",IFERROR(INDIRECT("'"&A6&"'!H3"),"")) | F6: =IF(A6="","",IFERROR(INDIRECT("'"&A6&"'!L3"),""))
B7: =IF(A7="","",IFERROR(INDIRECT("'"&A7&"'!J3"),"")) | C7: =IF(A7="","",IFERROR(INDEX(INDIRECT("'"&A7&"'!A6:A200"),MATCH(TRUE,INDEX(INDIRECT("'"&A7&"'!A6:A200")<>"",0),0)),"")) | E7: =IF(A7="","",IFERROR(INDIRECT("'"&A7&"'!H3"),"")) | F7: =IF(A7="","",IFERROR(INDIRECT("'"&A7&"'!L3"),""))
B8: =IF(A8="","",IFERROR(INDIRECT("'"&A8&"'!J3"),"")) | C8: =IF(A8="","",IFERROR(INDEX(INDIRECT("'"&A8&"'!A6:A200"),MATCH(TRUE,INDEX(INDIRECT("'"&A8&"'!A6:A200")<>"",0),0)),"")) | E8: =IF(A8="","",IFERROR(INDIRECT("'"&A8&"'!H3"),"")) | F8: =IF(A8="","",IFERROR(INDIRECT("'"&A8&"'!L3"),""))
B9: =IF(A9="","",IFERROR(INDIRECT("'"&A9&"'!J3"),"")) | C9: =IF(A9="","",IFERROR(INDEX(INDIRECT("'"&A9&"'!A6:A200"),MATCH(TRUE,INDEX(INDIRECT("'"&A9&"'!A6:A200")<>"",0),0)),"")) | E9: =IF(A9="","",IFERROR(INDIRECT("'"&A9&"'!H3"),"")) | F9: =IF(A9="","",IFERROR(INDIRECT("'"&A9&"'!L3"),""))
B10: =IF(A10="","",IFERROR(INDIRECT("'"&A10&"'!J3"),"")) | C10: =IF(A10="","",IFERROR(INDEX(INDIRECT("'"&A10&"'!A6:A200"),MATCH(TRUE,INDEX(INDIRECT("'"&A10&"'!A6:A200")<>"",0),0)),"")) | E10: =IF(A10="","",IFERROR(INDIRECT("'"&A10&"'!H3"),"")) | F10: =IF(A10="","",IFERROR(INDIRECT("'"&A10&"'!L3"),""))
B11: =IF(A11="","",IFERROR(INDIRECT("'"&A11&"'!J3"),"")) | C11: =IF(A11="","",IFERROR(INDEX(INDIRECT("'"&A11&"'!A6:A200"),MATCH(TRUE,INDEX(INDIRECT("'"&A11&"'!A6:A200")<>"",0),0)),"")) | E11: =IF(A11="","",IFERROR(INDIRECT("'"&A11&"'!H3"),"")) | F11: =IF(A11="","",IFERROR(INDIRECT("'"&A11&"'!L3"),""))
B12: =IF(A12="","",IFERROR(INDIRECT("'"&A12&"'!J3"),"")) | C12: =IF(A12="","",IFERROR(INDEX(INDIRECT("'"&A12&"'!A6:A200"),MATCH(TRUE,INDEX(INDIRECT("'"&A12&"'!A6:A200")<>"",0),0)),"")) | E12: =IF(A12="","",IFERROR(INDIRECT("'"&A12&"'!H3"),"")) | F12: =IF(A12="","",IFERROR(INDIRECT("'"&A12&"'!L3"),""))
B13: =IF(A13="","",IFERROR(INDIRECT("'"&A13&"'!J3"),"")) | C13: =IF(A13="","",IFERROR(INDEX(INDIRECT("'"&A13&"'!A6:A200"),MATCH(TRUE,INDEX(INDIRECT("'"&A13&"'!A6:A200")<>"",0),0)),"")) | E13: =IF(A13="","",IFERROR(INDIRECT("'"&A13&"'!H3"),"")) | F13: =IF(A13="","",IFERROR(INDIRECT("'"&A13&"'!L3"),""))
B14: =IF(A14="","",IFERROR(INDIRECT("'"&A14&"'!J3"),"")) | C14: =IF(A14="","",IFERROR(INDEX(INDIRECT("'"&A14&"'!A6:A200"),MATCH(TRUE,INDEX(INDIRECT("'"&A14&"'!A6:A200")<>"",0),0)),"")) | E14: =IF(A14="","",IFERROR(INDIRECT("'"&A14&"'!H3"),"")) | F14: =IF(A14="","",IFERROR(INDIRECT("'"&A14&"'!L3"),""))
B15: =IF(A15="","",IFERROR(INDIRECT("'"&A15&"'!J3"),"")) | C15: =IF(A15="","",IFERROR(INDEX(INDIRECT("'"&A15&"'!A6:A200"),MATCH(TRUE,INDEX(INDIRECT("'"&A15&"'!A6:A200")<>"",0),0)),"")) | E15: =IF(A15="","",IFERROR(INDIRECT("'"&A15&"'!H3"),"")) | F15: =IF(A15="","",IFERROR(INDIRECT("'"&A15&"'!L3"),""))
B16: =IF(A16="","",IFERROR(INDIRECT("'"&A16&"'!J3"),"")) | C16: =IF(A16="","",IFERROR(INDEX(INDIRECT("'"&A16&"'!A6:A200"),MATCH(TRUE,INDEX(INDIRECT("'"&A16&"'!A6:A200")<>"",0),0)),"")) | E16: =IF(A16="","",IFERROR(INDIRECT("'"&A16&"'!H3"),"")) | F16: =IF(A16="","",IFERROR(INDIRECT("'"&A16&"'!L3"),""))
B17: =IF(A17="","",IFERROR(INDIRECT("'"&A17&"'!J3"),"")) | C17: =IF(A17="","",IFERROR(INDEX(INDIRECT("'"&A17&"'!A6:A200"),MATCH(TRUE,INDEX(INDIRECT("'"&A17&"'!A6:A200")<>"",0),0)),"")) | E17: =IF(A17="","",IFERROR(INDIRECT("'"&A17&"'!H3"),"")) | F17: =IF(A17="","",IFERROR(INDIRECT("'"&A17&"'!L3"),""))
... B35: =IF(A35="","",IFERROR(INDIRECT("'"&A35&"'!J3"),"")) | C35: =IF(A35="","",IFERROR(INDEX(INDIRECT("'"&A35&"'!A6:A200"),MATCH(TRUE,INDEX(INDIRECT("'"&A35&"'!A6:A200")<>"",0),0)),"")) | E35: =IF(A35="","",IFERROR(INDIRECT("'"&A35&"'!H3"),"")) | F35: =IF(A35="","",IFERROR(INDIRECT("'"&A35&"'!L3"),""))
A36: EVICTION / UNPAID ARREARS: Set Reason = Eviction. Set Arrears Outcome = Written off (or Still pursuing). Final Balance = amount left unpaid. Notes = notice date, lock date, deposit applied, and whether you will pursue further. Then clear the unit sheet so the next tenant starts at 0.
A37: DETAILED TRANSACTION HISTORY (paste full ledger rows here when a tenant leaves)
A38: Include Unit and Tenant Name on every row so you can filter later. Copy Date, Month, Description, Rent, Garbage, Payment, M-Pesa Ref, Running Balance, Remarks from the unit sheet.
A39: Unit | B39: Tenant Name | C39: Date | D39: Month | E39: Description | F39: Rent Charged | G39: Garbage Charged | H39: Payment Received | I39: M-Pesa Reference | J39: Running Balance | K39: Remarks | L39: Archived On

Sheet Instructions
A1: HOW TO USE THIS WORKBOOK
A4: SHEETS OVERVIEW
A5: Summary | B5: All current units — balances, priority, suggested action.
A6: Statement | B6: Printable / PDF statement for the CURRENT tenant of any unit.
A7: Archive | B7: History of PREVIOUS tenants. Unit sheets stay current-tenant only.
A8: A1 – Shop 2 | B8: One ledger per unit — current tenant only.
A10: DAILY / WEEKLY USE
A11: 1. Open Summary | B11: Check Priority column and Unit Status table at the bottom.
A12: 2. Record payments | B12: Go to the unit sheet → use blank rows at the bottom.
A13: 3. Monthly charge | B13: Select Month in column B → Date & Description fill automatically.
A14: 4. Payment | B14: Leave Month blank → choose Payment Received → enter Amount + M-Pesa Ref.
A16: WHEN A TENANT VACATES
A17: Step 1 — Settle | B17: Enter final charges and payments. Clear the balance if possible.
A18: Step 2 — Deposit | B18: Refund or forfeit. Update Deposit Held (L3) to 0 when settled.
A19: Step 3 — Archive register | B19: On Archive sheet, fill one row in CLOSED TENANCIES REGISTER (unit, name, dates, final balance, deposit outcome).
A20: Step 4 — Archive transactions | B20: Copy all transaction rows from the unit sheet into DETAILED TRANSACTION HISTORY on Archive. Add Unit + Tenant Name on every row. Put today’s date in Archived On.
A21: Step 5 — Clear unit sheet | B21: Delete the transaction rows on the unit sheet (keep the header row 1–5). Running Balance will restart at 0 for the next tenant.
A22: Step 6 — Remarks | B22: Optional: leave a note in Remarks on Archive: “Vacated [date]”.
A24: WHEN A NEW TENANT JOINS
A25: Step 1 — Confirm clear | B25: Unit sheet transaction area should be empty (only header + blank template rows).
A26: Step 2 — Update header | B26: J3 = new tenant name. D3 = rent. F3 = garbage. L3 = deposit received.
A27: Step 3 — First charge | B27: Select the move-in month in column B to create the first Monthly Rent Charge.
A28: Step 4 — Deposit note | B28: Record deposit as Payment Received (or note in Remarks) and keep L3 updated.
A29: Step 5 — Check Summary | B29: New name and balance should appear automatically.
A31: TENANT STATEMENT
A32: Current tenant | B32: Statement sheet → change yellow cell B3 to the unit → Print or Save as PDF.
A33: Previous tenant | B33: Go to Archive → filter by Tenant Name → copy the rows you need, or recreate a simple statement from the archived data.
A35: COLOUR & PRIORITY
A36: PAID (green) | B36: NO ACTION NEEDED
A37: LOW (yellow) | B37: MONITOR
A38: MEDIUM (orange) | B38: FOLLOW UP
A39: HIGH (red) | B39: URGENT
A41: GOOGLE DRIVE & PHONE
A42: Master file | B42: One master copy on Google Drive.
A43: Editing | B43: Download → edit on computer → re-upload. Avoid simultaneous phone + computer edits.
A44: Viewing | B44: Phone is fine for checking balances and history.
A46: IMPORTANT RULES
A47: Unit sheet = current tenant only | B47: Never keep two tenants mixed on the same unit sheet.
A48: Never delete Archive rows | B48: History is permanent.
A49: Always record M-Pesa refs | B49: Protects you in disputes.
...

Sheet A1
A1: Unit A1 — Tenant Statement / Ledger
A2: Select a month to create a Monthly Rent Charge: the date fills as the first day of that month (current year) and description fills automatically. For a payment, leave Month blank and choose Payment Received.
A3: Unit | B3: A1 | C3: Current Rent | D3: 5000 | E3: Garbage | F3: 100 | G3: Current Balance | H3: =IFERROR(LOOKUP(9.99E+307,I6:I32),0) | I3: Tenant | J3: Colins Lugua | K3: Deposit Held | L3: 5000
A4: Current tenant only. When vacating → copy rows to Archive sheet, then clear this ledger.
A5: Date | B5: Month | C5: Description | D5: Tenant | E5: Rent Charged | F5: Garbage Charged | G5: Payment Received | H5: M-Pesa Reference | I5: Running Balance | J5: Remarks
A6: =IF(B6="","",DATE(YEAR(TODAY()),MATCH(B6,{"January","February","March","April","May","June","July","August","September","October","November","December"},0),1)) | B6: March | C6: =IF(B6="","","Monthly Rent Charge") | E6: 7500 | F6: =IF(C6="Monthly Rent Charge",$F$3,"") | I6: =IF(A6="","",IF(C6="Payment Received",-IFERROR(G6,0),IF(C6="Monthly Rent Charge",IFERROR(E6,0)+IFERROR(F6,0),0))) | J6: 5,000 Depo
A7: 46099 | C7: Payment Received | G7: 4900 | H7: UCIF49T5M4 | I7: =IF(A7="","",IF(C7="Payment Received",I6-IFERROR(G7,0),IF(C7="Monthly Rent Charge",I6+IFERROR(E7,0)+IFERROR(F7,0),I6)))
A8: 46103 | C8: Payment Received | G8: 2500 | H8: UCMF4A800A | I8: =IF(A8="","",IF(C8="Payment Received",I7-IFERROR(G8,0),IF(C8="Monthly Rent Charge",I7+IFERROR(E8,0)+IFERROR(F8,0),I7))) | J8: Depo cleared
A9: 46105 | C9: Payment Received | G9: 5000 | H9: UCOF4AG7GA | I9: =IF(A9="","",IF(C9="Payment Received",I8-IFERROR(G9,0),IF(C9="Monthly Rent Charge",I8+IFERROR(E9,0)+IFERROR(F9,0),I8)))
A10: 46113 | B10: April | C10: Monthly Rent Charge | E10: 5000 | F10: 100 | I10: =IF(A10="","",IF(C10="Payment Received",I9-IFERROR(G10,0),IF(C10="Monthly Rent Charge",I9+IFERROR(E10,0)+IFERROR(F10,0),I9)))
A11: 46143 | B11: May | C11: Monthly Rent Charge | E11: 5000 | F11: 100 | I11: =IF(A11="","",IF(C11="Payment Received",I10-IFERROR(G11,0),IF(C11="Monthly Rent Charge",I10+IFERROR(E11,0)+IFERROR(F11,0),I10)))
A12: 46146 | C12: Payment Received | G12: 5000 | H12: UE4F437KW2 | I12: =IF(A12="","",IF(C12="Payment Received",I11-IFERROR(G12,0),IF(C12="Monthly Rent Charge",I11+IFERROR(E12,0)+IFERROR(F12,0),I11)))
A13: 46174 | B13: June | C13: Monthly Rent Charge | E13: =IF(C13="Monthly Rent Charge",$D$3,"") | F13: =IF(C13="Monthly Rent Charge",$F$3,"") | I13: =IF(AND(A13="",C13=""),"",IF(C13="Payment Received",I12-IFERROR(G13,0),IF(C13="Monthly Rent Charge",I12+IFERROR(E13,0)+IFERROR(F13,0),I12)))
A14: 46176 | C14: Payment Received | E14: =IF(C14="Monthly Rent Charge",$D$3,"") | F14: =IF(C14="Monthly Rent Charge",$F$3,"") | G14: 5000 | H14: UF3F46N58H | I14: =IF(AND(A14="",C14=""),"",IF(C14="Payment Received",I13-IFERROR(G14,0),IF(C14="Monthly Rent Charge",I13+IFERROR(E14,0)+IFERROR(F14,0),I13)))
A15: =IF(B15="","",DATE(YEAR(TODAY()),MATCH(B15,{"January","February","March","April","May","June","July","August","September","October","November","December"},0),1)) | B15: July | C15: =IF(B15="","","Monthly Rent Charge") | E15: =IF(C15="Monthly Rent Charge",$D$3,"") | F15: =IF(C15="Monthly Rent Charge",$F$3,"") | I15: =IF(AND(A15="",C15=""),"",IF(C15="Payment Received",I14-IFERROR(G15,0),IF(C15="Monthly Rent Charge",I14+IFERROR(E15,0)+IFERROR(F15,0),I14)))
A16: 46206 | C16: Payment Received | E16: =IF(C16="Monthly Rent Charge",$D$3,"") | F16: =IF(C16="Monthly Rent Charge",$F$3,"") | G16: 5100 | I16: =IF(AND(A16="",C16=""),"",IF(C16="Payment Received",I15-IFERROR(G16,0),IF(C16="Monthly Rent Charge",I15+IFERROR(E16,0)+IFERROR(F16,0),I15)))
A17: =IF(B17="","",DATE(YEAR(TODAY()),MATCH(B17,{"January","February","March","April","May","June","July","August","September","October","November","December"},0),1)) | B17: August | C17: =IF(B17="","","Monthly Rent Charge") | E17: =IF(C17="Monthly Rent Charge",$D$3,"") | F17: =IF(C17="Monthly Rent Charge",$F$3,"") | I17: =IF(AND(A17="",C17=""),"",IF(C17="Payment Received",I16-IFERROR(G17,0),IF(C17="Monthly Rent Charge",I16+IFERROR(E17,0)+IFERROR(F17,0),I16)))
A18: =IF(B18="","",DATE(YEAR(TODAY()),MATCH(B18,{"January","February","March","April","May","June","July","August","September","October","November","December"},0),1)) | C18: =IF(B18="","","Monthly Rent Charge") | E18: =IF(C18="Monthly Rent Charge",$D$3,"") | F18: =IF(C18="Monthly Rent Charge",$F$3,"") | I18: =IF(AND(A18="",C18=""),"",IF(C18="Payment Received",I17-IFERROR(G18,0),IF(C18="Monthly Rent Charge",I17+IFERROR(E18,0)+IFERROR(F18,0),IFERROR(I17,0))))
A19: =IF(B19="","",DATE(YEAR(TODAY()),MATCH(B19,{"January","February","March","April","May","June","July","August","September","October","November","December"},0),1)) | C19: =IF(B19="","","Monthly Rent Charge") | E19: =IF(C19="Monthly Rent Charge",$D$3,"") | F19: =IF(C19="Monthly Rent Charge",$F$3,"") | I19: =IF(AND(A19="",C19=""),"",IF(C19="Payment Received",I18-IFERROR(G19,0),IF(C19="Monthly Rent Charge",I18+IFERROR(E19,0)+IFERROR(F19,0),IFERROR(I18,0))))
A20: =IF(B20="","",DATE(YEAR(TODAY()),MATCH(B20,{"January","February","March","April","May","June","July","August","September","October","November","December"},0),1)) | C20: =IF(B20="","","Monthly Rent Charge") | E20: =IF(C20="Monthly Rent Charge",$D$3,"") | F20: =IF(C20="Monthly Rent Charge",$F$3,"") | I20: =IF(AND(A20="",C20=""),"",IF(C20="Payment Received",I19-IFERROR(G20,0),IF(C20="Monthly Rent Charge",I19+IFERROR(E20,0)+IFERROR(F20,0),IFERROR(I19,0))))
A21: =IF(B21="","",DATE(YEAR(TODAY()),MATCH(B21,{"January","February","March","April","May","June","July","August","September","October","November","December"},0),1)) | C21: =IF(B21="","","Monthly Rent Charge") | E21: =IF(C21="Monthly Rent Charge",$D$3,"") | F21: =IF(C21="Monthly Rent Charge",$F$3,"") | I21: =IF(AND(A21="",C21=""),"",IF(C21="Payment Received",I20-IFERROR(G21,0),IF(C21="Monthly Rent Charge",I20+IFERROR(E21,0)+IFERROR(F21,0),IFERROR(I20,0))))
A22: =IF(B22="","",DATE(YEAR(TODAY()),MATCH(B22,{"January","February","March","April","May","June","July","August","September","October","November","December"},0),1)) | C22: =IF(B22="","","Monthly Rent Charge") | E22: =IF(C22="Monthly Rent Charge",$D$3,"") | F22: =IF(C22="Monthly Rent Charge",$F$3,"") | I22: =IF(AND(A22="",C22=""),"",IF(C22="Payment Received",I21-IFERROR(G22,0),IF(C22="Monthly Rent Charge",I21+IFERROR(E22,0)+IFERROR(F22,0),IFERROR(I21,0))))
A23: =IF(B23="","",DATE(YEAR(TODAY()),MATCH(B23,{"January","February","March","April","May","June","July","August","September","October","November","December"},0),1)) | C23: =IF(B23="","","Monthly Rent Charge") | E23: =IF(C23="Monthly Rent Charge",$D$3,"") | F23: =IF(C23="Monthly Rent Charge",$F$3,"") | I23: =IF(AND(A23="",C23=""),"",IF(C23="Payment Received",I22-IFERROR(G23,0),IF(C23="Monthly Rent Charge",I22+IFERROR(E23,0)+IFERROR(F23,0),IFERROR(I22,0))))
A24: =IF(B24="","",DATE(YEAR(TODAY()),MATCH(B24,{"January","February","March","April","May","June","July","August","September","October","November","December"},0),1)) | C24: =IF(B24="","","Monthly Rent Charge") | E24: =IF(C24="Monthly Rent Charge",$D$3,"") | F24: =IF(C24="Monthly Rent Charge",$F$3,"") | I24: =IF(AND(A24="",C24=""),"",IF(C24="Payment Received",I23-IFERROR(G24,0),IF(C24="Monthly Rent Charge",I23+IFERROR(E24,0)+IFERROR(F24,0),IFERROR(I23,0))))
A25: =IF(B25="","",DATE(YEAR(TODAY()),MATCH(B25,{"January","February","March","April","May","June","July","August","September","October","November","December"},0),1)) | C25: =IF(B25="","","Monthly Rent Charge") | E25: =IF(C25="Monthly Rent Charge",$D$3,"") | F25: =IF(C25="Monthly Rent Charge",$F$3,"") | I25: =IF(AND(A25="",C25=""),"",IF(C25="Payment Received",I24-IFERROR(G25,0),IF(C25="Monthly Rent Charge",I24+IFERROR(E25,0)+IFERROR(F25,0),IFERROR(I24,0))))
A26: =IF(B26="","",DATE(YEAR(TODAY()),MATCH(B26,{"January","February","March","April","May","June","July","August","September","October","November","December"},0),1)) | C26: =IF(B26="","","Monthly Rent Charge") | E26: =IF(C26="Monthly Rent Charge",$D$3,"") | F26: =IF(C26="Monthly Rent Charge",$F$3,"") | I26: =IF(AND(A26="",C26=""),"",IF(C26="Payment Received",I25-IFERROR(G26,0),IF(C26="Monthly Rent Charge",I25+IFERROR(E26,0)+IFERROR(F26,0),IFERROR(I25,0))))
A27: =IF(B27="","",DATE(YEAR(TODAY()),MATCH(B27,{"January","February","March","April","May","June","July","August","September","October","November","December"},0),1)) | C27: =IF(B27="","","Monthly Rent Charge") | E27: =IF(C27="Monthly Rent Charge",$D$3,"") | F27: =IF(C27="Monthly Rent Charge",$F$3,"") | I27: =IF(AND(A27="",C27=""),"",IF(C27="Payment Received",I26-IFERROR(G27,0),IF(C27="Monthly Rent Charge",I26+IFERROR(E27,0)+IFERROR(F27,0),IFERROR(I26,0))))
A28: =IF(B28="","",DATE(YEAR(TODAY()),MATCH(B28,{"January","February","March","April","May","June","July","August","September","October","November","December"},0),1)) | C28: =IF(B28="","","Monthly Rent Charge") | E28: =IF(C28="Monthly Rent Charge",$D$3,"") | F28: =IF(C28="Monthly Rent Charge",$F$3,"") | I28: =IF(AND(A28="",C28=""),"",IF(C28="Payment Received",I27-IFERROR(G28,0),IF(C28="Monthly Rent Charge",I27+IFERROR(E28,0)+IFERROR(F28,0),IFERROR(I27,0))))
A29: =IF(B29="","",DATE(YEAR(TODAY()),MATCH(B29,{"January","February","March","April","May","June","July","August","September","October","November","December"},0),1)) | C29: =IF(B29="","","Monthly Rent Charge") | E29: =IF(C29="Monthly Rent Charge",$D$3,"") | F29: =IF(C29="Monthly Rent Charge",$F$3,"") | I29: =IF(AND(A29="",C29=""),"",IF(C29="Payment Received",I28-IFERROR(G29,0),IF(C29="Monthly Rent Charge",I28+IFERROR(E29,0)+IFERROR(F29,0),IFERROR(I28,0))))
... A32: =IF(B32="","",DATE(YEAR(TODAY()),MATCH(B32,{"January","February","March","April","May","June","July","August","September","October","November","December"},0),1)) | C32: =IF(B32="","","Monthly Rent Charge") | E32: =IF(C32="Monthly Rent Charge",$D$3,"") | F32: =IF(C32="Monthly Rent Charge",$F$3,"") | I32: =IF(AND(A32="",C32=""),"",IF(C32="Payment Received",I31-IFERROR(G32,0),IF(C32="Monthly Rent Charge",I31+IFERROR(E32,0)+IFERROR(F32,0),IFERROR(I31,0))))

Sheet A2
A1: Unit A2 — Tenant Statement / Ledger
A2: Select a month to create a Monthly Rent Charge: the date fills as the first day of that month (current year) and description fills automatically. For a payment, leave Month blank and choose Payment Received.
A3: Unit | B3: A2 | C3: Current Rent | D3: 4500 | E3: Garbage | F3: 0 | G3: Current Balance | H3: =IFERROR(LOOKUP(9.99E+307,I6:I75),0) | I3: Tenant | J3: KATIWA KAMENE | K3: Deposit Held | L3: 0
A4: Current tenant only. When vacating → copy rows to Archive sheet, then clear this ledger.
A5: Date | B5: Month | C5: Description | D5: Tenant | E5: Rent Charged | F5: Garbage Charged | G5: Payment Received | H5: M-Pesa Reference | I5: Running Balance | J5: Remarks
A6: 45413 | B6: May | C6: Monthly Rent Charge | E6: =IF(C6="Monthly Rent Charge",$D$3,"") | F6: =IF(C6="Monthly Rent Charge",$F$3,"") | I6: =IF(A6="","",IF(C6="Payment Received",-IFERROR(G6,0),IF(C6="Monthly Rent Charge",IFERROR(E6,0)+IFERROR(F6,0),0)))
A7: 45417 | C7: Payment Received | E7: =IF(C7="Monthly Rent Charge",$D$3,"") | F7: =IF(C7="Monthly Rent Charge",$F$3,"") | G7: 4500 | H7: SE57AGDEVX | I7: =IF(A7="","",IF(C7="Payment Received",I6-IFERROR(G7,0),IF(C7="Monthly Rent Charge",I6+IFERROR(E7,0)+IFERROR(F7,0),I6)))
A8: 45444 | B8: June | C8: Monthly Rent Charge | E8: =IF(C8="Monthly Rent Charge",$D$3,"") | F8: =IF(C8="Monthly Rent Charge",$F$3,"") | I8: =IF(A8="","",IF(C8="Payment Received",I7-IFERROR(G8,0),IF(C8="Monthly Rent Charge",I7+IFERROR(E8,0)+IFERROR(F8,0),I7)))
A9: 45448 | C9: Payment Received | E9: =IF(C9="Monthly Rent Charge",$D$3,"") | F9: =IF(C9="Monthly Rent Charge",$F$3,"") | G9: 4500 | H9: SF54JVEV5Y | I9: =IF(A9="","",IF(C9="Payment Received",I8-IFERROR(G9,0),IF(C9="Monthly Rent Charge",I8+IFERROR(E9,0)+IFERROR(F9,0),I8)))
A10: 45474 | B10: July | C10: =IF(B10="","","Monthly Rent Charge") | E10: =IF(C10="Monthly Rent Charge",$D$3,"") | F10: =IF(C10="Monthly Rent Charge",$F$3,"") | I10: =IF(A10="","",IF(C10="Payment Received",I9-IFERROR(G10,0),IF(C10="Monthly Rent Charge",I9+IFERROR(E10,0)+IFERROR(F10,0),I9)))
A11: 45479 | C11: Payment Received | E11: =IF(C11="Monthly Rent Charge",$D$3,"") | F11: =IF(C11="Monthly Rent Charge",$F$3,"") | G11: 4500 | H11: SG63QGNDV9 | I11: =IF(A11="","",IF(C11="Payment Received",I10-IFERROR(G11,0),IF(C11="Monthly Rent Charge",I10+IFERROR(E11,0)+IFERROR(F11,0),I10)))
A12: 45505 | B12: August | C12: =IF(B12="","","Monthly Rent Charge") | E12: =IF(C12="Monthly Rent Charge",$D$3,"") | F12: =IF(C12="Monthly Rent Charge",$F$3,"") | I12: =IF(A12="","",IF(C12="Payment Received",I11-IFERROR(G12,0),IF(C12="Monthly Rent Charge",I11+IFERROR(E12,0)+IFERROR(F12,0),I11)))
A13: 45510 | C13: Payment Received | E13: =IF(C13="Monthly Rent Charge",$D$3,"") | F13: =IF(C13="Monthly Rent Charge",$F$3,"") | G13: 4500 | H13: SH654CXXY9 | I13: =IF(A13="","",IF(C13="Payment Received",I12-IFERROR(G13,0),IF(C13="Monthly Rent Charge",I12+IFERROR(E13,0)+IFERROR(F13,0),I12)))
A14: 45536 | B14: September | C14: =IF(B14="","","Monthly Rent Charge") | E14: =IF(C14="Monthly Rent Charge",$D$3,"") | F14: =IF(C14="Monthly Rent Charge",$F$3,"") | I14: =IF(A14="","",IF(C14="Payment Received",I13-IFERROR(G14,0),IF(C14="Monthly Rent Charge",I13+IFERROR(E14,0)+IFERROR(F14,0),I13)))
A15: 45542 | C15: Payment Received | E15: =IF(C15="Monthly Rent Charge",$D$3,"") | F15: =IF(C15="Monthly Rent Charge",$F$3,"") | G15: 4500 | H15: SI72PLCW0I | I15: =IF(A15="","",IF(C15="Payment Received",I14-IFERROR(G15,0),IF(C15="Monthly Rent Charge",I14+IFERROR(E15,0)+IFERROR(F15,0),I14)))
A16: 45566 | B16: October | C16: =IF(B16="","","Monthly Rent Charge") | E16: =IF(C16="Monthly Rent Charge",$D$3,"") | F16: =IF(C16="Monthly Rent Charge",$F$3,"") | I16: =IF(A16="","",IF(C16="Payment Received",I15-IFERROR(G16,0),IF(C16="Monthly Rent Charge",I15+IFERROR(E16,0)+IFERROR(F16,0),I15)))
A17: 45571 | C17: Payment Received | E17: =IF(C17="Monthly Rent Charge",$D$3,"") | F17: =IF(C17="Monthly Rent Charge",$F$3,"") | G17: 4500 | H17: SJ643CA9I2 | I17: =IF(A17="","",IF(C17="Payment Received",I16-IFERROR(G17,0),IF(C17="Monthly Rent Charge",I16+IFERROR(E17,0)+IFERROR(F17,0),I16)))
A18: 45597 | B18: November | C18: Monthly Rent Charge | E18: =IF(C18="Monthly Rent Charge",$D$3,"") | F18: =IF(C18="Monthly Rent Charge",$F$3,"") | I18: =IF(A18="","",IF(C18="Payment Received",I17-IFERROR(G18,0),IF(C18="Monthly Rent Charge",I17+IFERROR(E18,0)+IFERROR(F18,0),I17)))
A19: 45602 | C19: Payment Received | E19: =IF(C19="Monthly Rent Charge",$D$3,"") | F19: =IF(C19="Monthly Rent Charge",$F$3,"") | G19: 3000 | H19: SK67U4HX7V | I19: =IF(A19="","",IF(C19="Payment Received",I18-IFERROR(G19,0),IF(C19="Monthly Rent Charge",I18+IFERROR(E19,0)+IFERROR(F19,0),I18)))
A20: 45627 | B20: December | C20: Monthly Rent Charge | E20: =IF(C20="Monthly Rent Charge",$D$3,"") | F20: =IF(C20="Monthly Rent Charge",$F$3,"") | I20: =IF(A20="","",IF(C20="Payment Received",I19-IFERROR(G20,0),IF(C20="Monthly Rent Charge",I19+IFERROR(E20,0)+IFERROR(F20,0),I19)))
A21: 45631 | C21: Payment Received | E21: =IF(C21="Monthly Rent Charge",$D$3,"") | F21: =IF(C21="Monthly Rent Charge",$F$3,"") | G21: 4500 | H21: SL59DSH8KN | I21: =IF(A21="","",IF(C21="Payment Received",I20-IFERROR(G21,0),IF(C21="Monthly Rent Charge",I20+IFERROR(E21,0)+IFERROR(F21,0),I20)))
A22: 45658 | B22: January | C22: Monthly Rent Charge | E22: =IF(C22="Monthly Rent Charge",$D$3,"") | F22: =IF(C22="Monthly Rent Charge",$F$3,"") | I22: =IF(A22="","",IF(C22="Payment Received",I21-IFERROR(G22,0),IF(C22="Monthly Rent Charge",I21+IFERROR(E22,0)+IFERROR(F22,0),I21)))
A23: 45663 | C23: Payment Received | E23: =IF(C23="Monthly Rent Charge",$D$3,"") | F23: =IF(C23="Monthly Rent Charge",$F$3,"") | G23: 4500 | H23: TA608ISC04 | I23: =IF(A23="","",IF(C23="Payment Received",I22-IFERROR(G23,0),IF(C23="Monthly Rent Charge",I22+IFERROR(E23,0)+IFERROR(F23,0),I22)))
A24: 45689 | B24: February | C24: Monthly Rent Charge | E24: =IF(C24="Monthly Rent Charge",$D$3,"") | F24: =IF(C24="Monthly Rent Charge",$F$3,"") | I24: =IF(A24="","",IF(C24="Payment Received",I23-IFERROR(G24,0),IF(C24="Monthly Rent Charge",I23+IFERROR(E24,0)+IFERROR(F24,0),I23)))
A25: 45694 | C25: Payment Received | E25: =IF(C25="Monthly Rent Charge",$D$3,"") | F25: =IF(C25="Monthly Rent Charge",$F$3,"") | G25: 6000 | H25: TB681U2C3U | I25: =IF(A25="","",IF(C25="Payment Received",I24-IFERROR(G25,0),IF(C25="Monthly Rent Charge",I24+IFERROR(E25,0)+IFERROR(F25,0),I24)))
A26: 45717 | B26: March | C26: Monthly Rent Charge | E26: =IF(C26="Monthly Rent Charge",$D$3,"") | F26: =IF(C26="Monthly Rent Charge",$F$3,"") | I26: =IF(A26="","",IF(C26="Payment Received",I25-IFERROR(G26,0),IF(C26="Monthly Rent Charge",I25+IFERROR(E26,0)+IFERROR(F26,0),I25)))
A27: 45727 | C27: Payment Received | E27: =IF(C27="Monthly Rent Charge",$D$3,"") | F27: =IF(C27="Monthly Rent Charge",$F$3,"") | G27: 4500 | H27: TCB6808HS0 | I27: =IF(A27="","",IF(C27="Payment Received",I26-IFERROR(G27,0),IF(C27="Monthly Rent Charge",I26+IFERROR(E27,0)+IFERROR(F27,0),I26)))
A28: 45748 | B28: April | C28: Monthly Rent Charge | E28: =IF(C28="Monthly Rent Charge",$D$3,"") | F28: =IF(C28="Monthly Rent Charge",$F$3,"") | I28: =IF(A28="","",IF(C28="Payment Received",I27-IFERROR(G28,0),IF(C28="Monthly Rent Charge",I27+IFERROR(E28,0)+IFERROR(F28,0),I27)))
A29: 45754 | C29: Payment Received | E29: =IF(C29="Monthly Rent Charge",$D$3,"") | F29: =IF(C29="Monthly Rent Charge",$F$3,"") | G29: 4500 | H29: TD73T0MGB1 | I29: =IF(A29="","",IF(C29="Payment Received",I28-IFERROR(G29,0),IF(C29="Monthly Rent Charge",I28+IFERROR(E29,0)+IFERROR(F29,0),I28)))
A30: 45778 | B30: May | C30: Monthly Rent Charge | E30: =IF(C30="Monthly Rent Charge",$D$3,"") | F30: =IF(C30="Monthly Rent Charge",$F$3,"") | I30: =IF(A30="","",IF(C30="Payment Received",I29-IFERROR(G30,0),IF(C30="Monthly Rent Charge",I29+IFERROR(E30,0)+IFERROR(F30,0),I29)))
A31: 45782 | C31: Payment Received | E31: =IF(C31="Monthly Rent Charge",$D$3,"") | F31: =IF(C31="Monthly Rent Charge",$F$3,"") | G31: 4500 | H31: TE58KFI578 | I31: =IF(A31="","",IF(C31="Payment Received",I30-IFERROR(G31,0),IF(C31="Monthly Rent Charge",I30+IFERROR(E31,0)+IFERROR(F31,0),I30)))
A32: 45809 | B32: June | C32: Monthly Rent Charge | E32: =IF(C32="Monthly Rent Charge",$D$3,"") | F32: =IF(C32="Monthly Rent Charge",$F$3,"") | I32: =IF(A32="","",IF(C32="Payment Received",I31-IFERROR(G32,0),IF(C32="Monthly Rent Charge",I31+IFERROR(E32,0)+IFERROR(F32,0),I31)))
A33: 45815 | C33: Payment Received | E33: =IF(C33="Monthly Rent Charge",$D$3,"") | F33: =IF(C33="Monthly Rent Charge",$F$3,"") | G33: 4500 | H33: TF71YMZMWL | I33: =IF(A33="","",IF(C33="Payment Received",I32-IFERROR(G33,0),IF(C33="Monthly Rent Charge",I32+IFERROR(E33,0)+IFERROR(F33,0),I32)))
A34: 45839 | B34: July | C34: Monthly Rent Charge | E34: =IF(C34="Monthly Rent Charge",$D$3,"") | F34: =IF(C34="Monthly Rent Charge",$F$3,"") | I34: =IF(A34="","",IF(C34="Payment Received",I33-IFERROR(G34,0),IF(C34="Monthly Rent Charge",I33+IFERROR(E34,0)+IFERROR(F34,0),I33)))
A35: 45845 | C35: Payment Received | E35: =IF(C35="Monthly Rent Charge",$D$3,"") | F35: =IF(C35="Monthly Rent Charge",$F$3,"") | G35: 4500 | H35: TG74ZQPORC | I35: =IF(A35="","",IF(C35="Payment Received",I34-IFERROR(G35,0),IF(C35="Monthly Rent Charge",I34+IFERROR(E35,0)+IFERROR(F35,0),I34)))
A36: 45870 | B36: August | C36: Monthly Rent Charge | E36: =IF(C36="Monthly Rent Charge",$D$3,"") | F36: =IF(C36="Monthly Rent Charge",$F$3,"") | I36: =IF(A36="","",IF(C36="Payment Received",I35-IFERROR(G36,0),IF(C36="Monthly Rent Charge",I35+IFERROR(E36,0)+IFERROR(F36,0),I35)))
A37: 45874 | C37: Payment Received | E37: =IF(C37="Monthly Rent Charge",$D$3,"") | F37: =IF(C37="Monthly Rent Charge",$F$3,"") | G37: 4500 | H37: TH503DKKO4 | I37: =IF(A37="","",IF(C37="Payment Received",I36-IFERROR(G37,0),IF(C37="Monthly Rent Charge",I36+IFERROR(E37,0)+IFERROR(F37,0),I36)))
A38: 45901 | B38: September | C38: Monthly Rent Charge | E38: =IF(C38="Monthly Rent Charge",$D$3,"") | F38: =IF(C38="Monthly Rent Charge",$F$3,"") | I38: =IF(A38="","",IF(C38="Payment Received",I37-IFERROR(G38,0),IF(C38="Monthly Rent Charge",I37+IFERROR(E38,0)+IFERROR(F38,0),I37)))
A39: 45906 | C39: Payment Received | E39: =IF(C39="Monthly Rent Charge",$D$3,"") | F39: =IF(C39="Monthly Rent Charge",$F$3,"") | G39: 4500 | H39: TI61MELPOJ | I39: =IF(A39="","",IF(C39="Payment Received",I38-IFERROR(G39,0),IF(C39="Monthly Rent Charge",I38+IFERROR(E39,0)+IFERROR(F39,0),I38)))
A40: 45931 | B40: October | C40: Monthly Rent Charge | E40: =IF(C40="Monthly Rent Charge",$D$3,"") | F40: =IF(C40="Monthly Rent Charge",$F$3,"") | I40: =IF(A40="","",IF(C40="Payment Received",I39-IFERROR(G40,0),IF(C40="Monthly Rent Charge",I39+IFERROR(E40,0)+IFERROR(F40,0),I39)))
...

Sheet A3
A1: Unit A3 — Tenant Statement / Ledger
A2: Select a month to create a Monthly Rent Charge: the date fills as the first day of that month (current year) and description fills automatically. For a payment, leave Month blank and choose Payment Received.
A3: Unit | B3: A3 | C3: Current Rent | D3: 4500 | E3: Garbage | F3: 200 | G3: Current Balance | H3: =IFERROR(LOOKUP(9.99E+307,I6:I33),0) | I3: Tenant | J3: Shaline Chepkirui/HILARY | K3: Deposit Held | L3: 4500
A4: Current tenant only. When vacating → copy rows to Archive sheet, then clear this ledger.
A5: Date | B5: Month | C5: Description | D5: Tenant | E5: Rent Charged | F5: Garbage Charged | G5: Payment Received | H5: M-Pesa Reference | I5: Running Balance | J5: Remarks
A6: =IF(B6="","",DATE(YEAR(TODAY()),MATCH(B6,{"January","February","March","April","May","June","July","August","September","October","November","December"},0),1)) | B6: January | C6: =IF(B6="","","Monthly Rent Charge") | E6: =IF(C6="Monthly Rent Charge",$D$3,"") | F6: =IF(C6="Monthly Rent Charge",$F$3,"") | I6: =IF(A6="","",IF(C6="Payment Received",-IFERROR(G6,0),IF(C6="Monthly Rent Charge",IFERROR(E6,0)+IFERROR(F6,0),0))) | J6: Depo c/f from previous tenant
A7: 46035 | C7: Payment Received | E7: =IF(C7="Monthly Rent Charge",$D$3,"") | F7: =IF(C7="Monthly Rent Charge",$F$3,"") | G7: 4500 | H7: UADFU3JC98 | I7: =IF(A7="","",IF(C7="Payment Received",I6-IFERROR(G7,0),IF(C7="Monthly Rent Charge",I6+IFERROR(E7,0)+IFERROR(F7,0),I6)))
A8: =IF(B8="","",DATE(YEAR(TODAY()),MATCH(B8,{"January","February","March","April","May","June","July","August","September","October","November","December"},0),1)) | B8: February | C8: =IF(B8="","","Monthly Rent Charge") | E8: =IF(C8="Monthly Rent Charge",$D$3,"") | F8: =IF(C8="Monthly Rent Charge",$F$3,"") | I8: =IF(A8="","",IF(C8="Payment Received",I7-IFERROR(G8,0),IF(C8="Monthly Rent Charge",I7+IFERROR(E8,0)+IFERROR(F8,0),I7)))
A9: 46061 | C9: Payment Received | E9: =IF(C9="Monthly Rent Charge",$D$3,"") | F9: =IF(C9="Monthly Rent Charge",$F$3,"") | G9: 4500 | H9: UB8F264RJM | I9: =IF(A9="","",IF(C9="Payment Received",I8-IFERROR(G9,0),IF(C9="Monthly Rent Charge",I8+IFERROR(E9,0)+IFERROR(F9,0),I8)))
A10: =IF(B10="","",DATE(YEAR(TODAY()),MATCH(B10,{"January","February","March","April","May","June","July","August","September","October","November","December"},0),1)) | B10: March | C10: =IF(B10="","","Monthly Rent Charge") | E10: =IF(C10="Monthly Rent Charge",$D$3,"") | F10: =IF(C10="Monthly Rent Charge",$F$3,"") | I10: =IF(A10="","",IF(C10="Payment Received",I9-IFERROR(G10,0),IF(C10="Monthly Rent Charge",I9+IFERROR(E10,0)+IFERROR(F10,0),I9)))
A11: 46088 | C11: Payment Received | E11: =IF(C11="Monthly Rent Charge",$D$3,"") | G11: 5100 | H11: UC7O98C3B3 | I11: =IF(A11="","",IF(C11="Payment Received",I10-IFERROR(G11,0),IF(C11="Monthly Rent Charge",I10+IFERROR(E11,0)+IFERROR(F11,0),I10)))
A12: =IF(B12="","",DATE(YEAR(TODAY()),MATCH(B12,{"January","February","March","April","May","June","July","August","September","October","November","December"},0),1)) | B12: April | C12: =IF(B12="","","Monthly Rent Charge") | E12: =IF(C12="Monthly Rent Charge",$D$3,"") | F12: =IF(C12="Monthly Rent Charge",$F$3,"") | I12: =IF(A12="","",IF(C12="Payment Received",I11-IFERROR(G12,0),IF(C12="Monthly Rent Charge",I11+IFERROR(E12,0)+IFERROR(F12,0),I11)))
A13: 46130 | C13: Payment Received | E13: =IF(C13="Monthly Rent Charge",$D$3,"") | F13: =IF(C13="Monthly Rent Charge",$F$3,"") | G13: 4700 | H13: UDIFU11SD2 | I13: =IF(A13="","",IF(C13="Payment Received",I12-IFERROR(G13,0),IF(C13="Monthly Rent Charge",I12+IFERROR(E13,0)+IFERROR(F13,0),I12)))
A14: =IF(B14="","",DATE(YEAR(TODAY()),MATCH(B14,{"January","February","March","April","May","June","July","August","September","October","November","December"},0),1)) | B14: May | C14: =IF(B14="","","Monthly Rent Charge") | E14: =IF(C14="Monthly Rent Charge",$D$3,"") | F14: =IF(C14="Monthly Rent Charge",$F$3,"") | I14: =IF(AND(A14="",C14=""),"",IF(C14="Payment Received",I13-IFERROR(G14,0),IF(C14="Monthly Rent Charge",I13+IFERROR(E14,0)+IFERROR(F14,0),I13)))
A15: 46158 | C15: Payment Received | E15: =IF(C15="Monthly Rent Charge",$D$3,"") | F15: =IF(C15="Monthly Rent Charge",$F$3,"") | G15: 4700 | H15: UEGF24H7JL | I15: =IF(AND(A15="",C15=""),"",IF(C15="Payment Received",I14-IFERROR(G15,0),IF(C15="Monthly Rent Charge",I14+IFERROR(E15,0)+IFERROR(F15,0),I14)))
A16: =IF(B16="","",DATE(YEAR(TODAY()),MATCH(B16,{"January","February","March","April","May","June","July","August","September","October","November","December"},0),1)) | B16: June | C16: =IF(B16="","","Monthly Rent Charge") | E16: =IF(C16="Monthly Rent Charge",$D$3,"") | F16: =IF(C16="Monthly Rent Charge",$F$3,"") | I16: =IF(AND(A16="",C16=""),"",IF(C16="Payment Received",I15-IFERROR(G16,0),IF(C16="Monthly Rent Charge",I15+IFERROR(E16,0)+IFERROR(F16,0),I15)))
A17: 46194 | C17: Payment Received | E17: =IF(C17="Monthly Rent Charge",$D$3,"") | F17: =IF(C17="Monthly Rent Charge",$F$3,"") | G17: 4700 | H17: UF11FU89MKJ | I17: =IF(AND(A17="",C17=""),"",IF(C17="Payment Received",I16-IFERROR(G17,0),IF(C17="Monthly Rent Charge",I16+IFERROR(E17,0)+IFERROR(F17,0),I16)))
A18: =IF(B18="","",DATE(YEAR(TODAY()),MATCH(B18,{"January","February","March","April","May","June","July","August","September","October","November","December"},0),1)) | B18: July | C18: =IF(B18="","","Monthly Rent Charge") | E18: =IF(C18="Monthly Rent Charge",$D$3,"") | F18: =IF(C18="Monthly Rent Charge",$F$3,"") | I18: =IF(AND(A18="",C18=""),"",IF(C18="Payment Received",I17-IFERROR(G18,0),IF(C18="Monthly Rent Charge",I17+IFERROR(E18,0)+IFERROR(F18,0),I17)))
A19: 46231 | C19: Payment Received | E19: =IF(C19="Monthly Rent Charge",$D$3,"") | F19: =IF(C19="Monthly Rent Charge",$F$3,"") | G19: 4700 | H19: UGSF20TNYT | I19: =IF(AND(A19="",C19=""),"",IF(C19="Payment Received",I18-IFERROR(G19,0),IF(C19="Monthly Rent Charge",I18+IFERROR(E19,0)+IFERROR(F19,0),IFERROR(I18,0))))
A20: =IF(B20="","",DATE(YEAR(TODAY()),MATCH(B20,{"January","February","March","April","May","June","July","August","September","October","November","December"},0),1)) | B20: August | C20: =IF(B20="","","Monthly Rent Charge") | E20: =IF(C20="Monthly Rent Charge",$D$3,"") | F20: =IF(C20="Monthly Rent Charge",$F$3,"") | I20: =IF(AND(A20="",C20=""),"",IF(C20="Payment Received",I19-IFERROR(G20,0),IF(C20="Monthly Rent Charge",I19+IFERROR(E20,0)+IFERROR(F20,0),IFERROR(I19,0))))
A21: 46258 | C21: Payment Received | E21: =IF(C21="Monthly Rent Charge",$D$3,"") | F21: =IF(C21="Monthly Rent Charge",$F$3,"") | G21: 4700 | H21: UHOF23XZXA | I21: =IF(AND(A21="",C21=""),"",IF(C21="Payment Received",I20-IFERROR(G21,0),IF(C21="Monthly Rent Charge",I20+IFERROR(E21,0)+IFERROR(F21,0),IFERROR(I20,0))))
A22: =IF(B22="","",DATE(YEAR(TODAY()),MATCH(B22,{"January","February","March","April","May","June","July","August","September","October","November","December"},0),1)) | C22: =IF(B22="","","Monthly Rent Charge") | E22: =IF(C22="Monthly Rent Charge",$D$3,"") | F22: =IF(C22="Monthly Rent Charge",$F$3,"") | I22: =IF(AND(A22="",C22=""),"",IF(C22="Payment Received",I21-IFERROR(G22,0),IF(C22="Monthly Rent Charge",I21+IFERROR(E22,0)+IFERROR(F22,0),IFERROR(I21,0))))
A23: =IF(B23="","",DATE(YEAR(TODAY()),MATCH(B23,{"January","February","March","April","May","June","July","August","September","October","November","December"},0),1)) | C23: =IF(B23="","","Monthly Rent Charge") | E23: =IF(C23="Monthly Rent Charge",$D$3,"") | F23: =IF(C23="Monthly Rent Charge",$F$3,"") | I23: =IF(AND(A23="",C23=""),"",IF(C23="Payment Received",I22-IFERROR(G23,0),IF(C23="Monthly Rent Charge",I22+IFERROR(E23,0)+IFERROR(F23,0),IFERROR(I22,0))))
